Workbook

Sheet All results
A1: timestamp | B1: split | C1: model | D1: vectorizer | E1: accuracy | F1: f1_weighted | G1: recall_weighted | H1: precision_weighted | I1: f1_macro | J1: recall_macro | K1: precision_macro | L1: f1_class_0 | M1: recall_class_0 | N1: precision_class_0 | O1: f1_class_1 | P1: recall_class_1 | Q1: precision_class_1 | R1: notes
A2: 45991.313 | B2: 50/50 split | C2: K-means | D2: TF-IDF | E2: 0.8447 | F2: 0.8255 | G2: 0.8447 | H2: 0.8451 | I2: 0.741 | J2: 0.7062 | K2: 0.8462 | L2: 0.9049 | M2: 0.9749 | N2: 0.8442 | O2: 0.5771 | P2: 0.4374 | Q2: 0.8481 | R2: test_1 | W2: 45991.313 | X2: 50/50 split | Y2: K-means | Z2: TF-IDF | AA2: 0.8447 | AB2: 0.8255 | AC2: 0.8447 | AD2: 0.8451 | AE2: 0.741 | AF2: 0.7062
A3: 45991.313 | B3: 50/50 split | C3: K-means | D3: TF-IDF | E3: 0.8445 | F3: 0.8254 | G3: 0.8445 | H3: 0.8446 | I3: 0.741 | J3: 0.7063 | K3: 0.8449 | L3: 0.9047 | M3: 0.9744 | N3: 0.8443 | O3: 0.5773 | P3: 0.4383 | Q3: 0.8456 | R3: test_2 | W3: 45991.313 | X3: 50/50 split | Y3: K-means | Z3: TF-IDF | AA3: 0.8445 | AB3: 0.8254 | AC3: 0.8445 | AD3: 0.8446 | AE3: 0.741 | AF3: 0.7063
A4: 45991.313 | B4: 50/50 split | C4: K-means | D4: TF-IDF | E4: 0.8446 | F4: 0.8254 | G4: 0.8446 | H4: 0.8449 | I4: 0.7411 | J4: 0.7063 | K4: 0.8456 | L4: 0.9048 | M4: 0.9747 | N4: 0.8443 | O4: 0.5774 | P4: 0.4379 | Q4: 0.847 | R4: test_3 | W4: 45991.313 | X4: 50/50 split | Y4: K-means | Z4: TF-IDF | AA4: 0.8446 | AB4: 0.8254 | AC4: 0.8446 | AD4: 0.8449 | AE4: 0.7411 | AF4: 0.7063
A5: 45991.314 | B5: 50/50 split | C5: K-means | D5: TF-IDF | E5: 0.8444 | F5: 0.8252 | G5: 0.8444 | H5: 0.8445 | I5: 0.7408 | J5: 0.7062 | K5: 0.8447 | L5: 0.9046 | M5: 0.9743 | N5: 0.8442 | O5: 0.577 | P5: 0.438 | Q5: 0.8452 | R5: test_4 | W5: 45991.314 | X5: 50/50 split | Y5: K-means | Z5: TF-IDF | AA5: 0.8444 | AB5: 0.8252 | AC5: 0.8444 | AD5: 0.8445 | AE5: 0.7408 | AF5: 0.7062
A6: 45991.314 | B6: 50/50 split | C6: K-means | D6: TF-IDF | E6: 0.8445 | F6: 0.8254 | G6: 0.8445 | H6: 0.8447 | I6: 0.741 | J6: 0.7064 | K6: 0.8451 | L6: 0.9047 | M6: 0.9745 | N6: 0.8443 | O6: 0.5774 | P6: 0.4383 | Q6: 0.8459 | R6: test_5 | W6: 45991.314 | X6: 50/50 split | Y6: K-means | Z6: TF-IDF | AA6: 0.8445 | AB6: 0.8254 | AC6: 0.8445 | AD6: 0.8447 | AE6: 0.741 | AF6: 0.7064
A7: 45991.314 | B7: 50/50 split | C7: HDBSCAN | D7: PCA | E7: 0.7952 | F7: 0.8076 | G7: 0.7952 | H7: 0.8497 | I7: 0.7611 | J7: 0.8177 | K7: 0.7476 | L7: 0.8514 | M7: 0.7741 | N7: 0.9458 | O7: 0.6709 | P7: 0.8613 | Q7: 0.5494 | R7: test_1
A8: 45991.315 | B8: 50/50 split | C8: HDBSCAN | D8: PCA | E8: 0.8321 | F8: 0.8423 | G8: 0.8321 | H8: 0.8841 | I8: 0.8042 | J8: 0.8681 | K8: 0.7868 | L8: 0.8781 | M8: 0.7983 | N8: 0.9757 | O8: 0.7303 | P8: 0.9378 | Q8: 0.598 | R8: test_2 | W8: 45991.389 | X8: 50/50 split | Y8: K-means | Z8: robust scaler | AA8: 0.817 | AB8: 0.7812 | AC8: 0.817 | AD8: 0.8236 | AE8: 0.6647 | AF8: 0.6396
A9: 45991.316 | B9: 50/50 split | C9: HDBSCAN | D9: PCA | E9: 0.8505 | F9: 0.8592 | G9: 0.8505 | H9: 0.8964 | I9: 0.8242 | J9: 0.8865 | K9: 0.8042 | L9: 0.8922 | M9: 0.8167 | N9: 0.9832 | O9: 0.7561 | P9: 0.9563 | Q9: 0.6253 | R9: test_3 | W9: 45991.39 | X9: 50/50 split | Y9: K-means | Z9: robust scaler | AA9: 0.8167 | AB9: 0.781 | AC9: 0.8167 | AD9: 0.8224 | AE9: 0.6647 | AF9: 0.6396
A10: 45991.317 | B10: 50/50 split | C10: HDBSCAN | D10: PCA | E10: 0.8443 | F10: 0.8534 | G10: 0.8443 | H10: 0.8914 | I10: 0.8171 | J10: 0.8791 | K10: 0.7979 | L10: 0.8876 | M10: 0.8115 | N10: 0.9794 | O10: 0.7466 | P10: 0.9467 | Q10: 0.6164 | R10: test_4 | W10: 45991.39 | X10: 50/50 split | Y10: K-means | Z10: robust scaler | AA10: 0.8164 | AB10: 0.7805 | AC10: 0.8164 | AD10: 0.8224 | AE10: 0.6638 | AF10: 0.6388
A11: 45991.319 | B11: 50/50 split | C11: HDBSCAN | D11: PCA | E11: 0.8465 | F11: 0.8553 | G11: 0.8465 | H11: 0.8913 | I11: 0.819 | J11: 0.8791 | K11: 0.7993 | L11: 0.8895 | M11: 0.8158 | N11: 0.9779 | O11: 0.7485 | P11: 0.9424 | Q11: 0.6208 | R11: test_5 | W11: 45991.39 | X11: 50/50 split | Y11: K-means | Z11: robust scaler | AA11: 0.8166 | AB11: 0.781 | AC11: 0.8166 | AD11: 0.8223 | AE11: 0.6646 | AF11: 0.6395
A12: 45991.319 | B12: 50/50 split | C12: IsolationForest | D12: TF-IDF | E12: 0.7612 | F12: 0.6677 | G12: 0.7612 | H12: 0.7384 | I12: 0.4598 | J12: 0.5123 | K12: 0.713 | L12: 0.8633 | M12: 0.9952 | N12: 0.7622 | O12: 0.0563 | P12: 0.0294 | Q12: 0.6638 | R12: test_1 | W12: 45991.39 | X12: 50/50 split | Y12: K-means | Z12: robust scaler | AA12: 0.8168 | AB12: 0.7811 | AC12: 0.8168 | AD12: 0.8226 | AE12: 0.6648 | AF12: 0.6397
A13: 45991.319 | B13: 50/50 split | C13: IsolationForest | D13: TF-IDF | E13: 0.7611 | F13: 0.668 | G13: 0.7611 | H13: 0.7356 | I13: 0.4605 | J13: 0.5126 | K13: 0.7073 | L13: 0.8632 | M13: 0.9948 | N13: 0.7623 | O13: 0.0578 | P13: 0.0303 | Q13: 0.6523 | R13: test_2
A14: 45991.319 | B14: 50/50 split | C14: IsolationForest | D14: TF-IDF | E14: 0.7611 | F14: 0.6677 | G14: 0.7611 | H14: 0.7365 | I14: 0.46 | J14: 0.5123 | K14: 0.7092 | L14: 0.8632 | M14: 0.995 | N14: 0.7622 | O14: 0.0567 | P14: 0.0296 | Q14: 0.6563 | R14: test_3 | W14: 45991.399 | X14: 50/50 split | Y14: K-means | Z14: Standard scaler | AA14: 0.833 | AB14: 0.8154 | AC14: 0.833 | AD14: 0.8258 | AE14: 0.7288 | AF14: 0.6992
A15: 45991.319 | B15: 50/50 split | C15: IsolationForest | D15: TF-IDF | E15: 0.7611 | F15: 0.6677 | G15: 0.7611 | H15: 0.7367 | I15: 0.46 | J15: 0.5124 | K15: 0.7096 | L15: 0.8632 | M15: 0.995 | N15: 0.7622 | O15: 0.0567 | P15: 0.0297 | Q15: 0.6571 | R15: test_4 | W15: 45991.399 | X15: 50/50 split | Y15: K-means | Z15: Standard scaler | AA15: 0.8327 | AB15: 0.8152 | AC15: 0.8327 | AD15: 0.8253 | AE15: 0.7285 | AF15: 0.6991
A16: 45991.319 | B16: 50/50 split | C16: IsolationForest | D16: TF-IDF | E16: 0.7608 | F16: 0.6672 | G16: 0.7608 | H16: 0.7344 | I16: 0.459 | J16: 0.5118 | K16: 0.7051 | L16: 0.8631 | M16: 0.995 | N16: 0.762 | O16: 0.0548 | P16: 0.0286 | Q16: 0.6482 | R16: test_5 | W16: 45991.399 | X16: 50/50 split | Y16: K-means | Z16: Standard scaler | AA16: 0.8327 | AB16: 0.8152 | AC16: 0.8327 | AD16: 0.8254 | AE16: 0.7285 | AF16: 0.699
A17: 45991.321 | B17: 50/50 split | C17: GMM | D17: PCA | E17: 0.9174 | F17: 0.9165 | G17: 0.9174 | H17: 0.9161 | I17: 0.885 | J17: 0.8765 | K17: 0.8945 | L17: 0.9461 | M17: 0.9559 | N17: 0.9364 | O17: 0.8239 | P17: 0.7971 | Q17: 0.8526 | R17: test_1 | W17: 45991.399 | X17: 50/50 split | Y17: K-means | Z17: Standard scaler | AA17: 0.8329 | AB17: 0.8153 | AC17: 0.8329 | AD17: 0.8257 | AE17: 0.7286 | AF17: 0.6991
A18: 45991.324 | B18: 50/50 split | C18: GMM | D18: PCA | E18: 0.8798 | F18: 0.8748 | G18: 0.8798 | H18: 0.8759 | I18: 0.8234 | J18: 0.8014 | K18: 0.8559 | L18: 0.9232 | M18: 0.9535 | N18: 0.8947 | O18: 0.7236 | P18: 0.6492 | Q18: 0.8171 | R18: test_2 | W18: 45991.399 | X18: 50/50 split | Y18: K-means | Z18: Standard scaler | AA18: 0.8331 | AB18: 0.8155 | AC18: 0.8331 | AD18: 0.8259 | AE18: 0.729 | AF18: 0.6995
A19: 45991.326 | B19: 50/50 split | C19: GMM | D19: PCA | E19: 0.888 | F19: 0.8852 | G19: 0.888 | H19: 0.8848 | I19: 0.8401 | J19: 0.825 | K19: 0.8594 | L19: 0.9276 | M19: 0.9473 | N19: 0.9088 | O19: 0.7525 | P19: 0.7027 | Q19: 0.81 | R19: test_3
A20: 45991.328 | B20: 50/50 split | C20: GMM | D20: PCA | E20: 0.8855 | F20: 0.8831 | G20: 0.8855 | H20: 0.8825 | I20: 0.8379 | J20: 0.8253 | K20: 0.8532 | L20: 0.9257 | M20: 0.9421 | N20: 0.9099 | O20: 0.75 | P20: 0.7086 | Q20: 0.7965 | R20: test_4 | W20: 45991.403 | X20: 50/50 split | Y20: HDBSCAN | Z20: Standard scaler | AA20: 0.7862 | AB20: 0.7999 | AC20: 0.7862 | AD20: 0.8496 | AE20: 0.754 | AF20: 0.8164 | AG20: 0.743 | AH20: 0.8431 | AI20: 0.7578 | AJ20: 0.9499 | AK20: 0.6649 | AL20: 0.8751 | AM20: 0.5361 | AN20: test_1
A21: 45991.332 | B21: 50/50 split | C21: GMM | D21: PCA | E21: 0.9021 | F21: 0.8991 | G21: 0.9021 | H21: 0.8997 | I21: 0.8589 | J21: 0.8401 | K21: 0.884 | L21: 0.937 | M21: 0.9604 | N21: 0.9146 | O21: 0.7808 | P21: 0.7197 | Q21: 0.8533 | R21: test_5 | W21: 45991.405 | X21: 50/50 split | Y21: HDBSCAN | Z21: Standard scaler | AA21: 0.8033 | AB21: 0.8152 | AC21: 0.8033 | AD21: 0.8564 | AE21: 0.7702 | AF21: 0.8275 | AG21: 0.7557 | AH21: 0.8574 | AI21: 0.7806 | AJ21: 0.951 | AK21: 0.683 | AL21: 0.8743 | AM21: 0.5604 | AN21: test_2
A22: 45991.304 | B22: 50/50 split | C22: AutoEncoder | D22: TF-IDF | E22: 0.8283 | F22: 0.8123 | G22: 0.8283 | H22: 0.8186 | I22: 0.726 | J22: 0.6991 | K22: 0.7922 | L22: 0.8935 | M22: 0.9499 | N22: 0.8433 | O22: 0.5586 | P22: 0.4482 | Q22: 0.7411 | R22: test_1 | W22: 45991.407 | X22: 50/50 split | Y22: HDBSCAN | Z22: Standard scaler | AA22: 0.7898 | AB22: 0.8039 | AC22: 0.7898 | AD22: 0.8639 | AE22: 0.7618 | AF22: 0.8349 | AG22: 0.7533 | AH22: 0.8434 | AI22: 0.7473 | AJ22: 0.9679 | AK22: 0.6802 | AL22: 0.9226 | AM22: 0.5387 | AN22: test_3
A23: 45991.305 | B23: 50/50 split | C23: AutoEncoder | D23: TF-IDF | E23: 0.8282 | F23: 0.8122 | G23: 0.8282 | H23: 0.8184 | I23: 0.726 | J23: 0.6991 | K23: 0.7918 | L23: 0.8933 | M23: 0.9496 | N23: 0.8434 | O23: 0.5587 | P23: 0.4486 | Q23: 0.7402 | R23: test_2 | W23: 45991.409 | X23: 50/50 split | Y23: HDBSCAN | Z23: Standard scaler | AA23: 0.8028 | AB23: 0.8151 | AC23: 0.8028 | AD23: 0.8612 | AE23: 0.7717 | AF23: 0.8339 | AG23: 0.7581 | AH23: 0.856 | AI23: 0.7736 | AJ23: 0.9581 | AK23: 0.6873 | AL23: 0.8942 | AM23: 0.5582 | AN23: test_4
A24: 45991.305 | B24: 50/50 split | C24: AutoEncoder | D24: TF-IDF | E24: 0.8279 | F24: 0.8118 | G24: 0.8279 | H24: 0.818 | I24: 0.7253 | J24: 0.6984 | K24: 0.7914 | L24: 0.8932 | M24: 0.9496 | N24: 0.843 | O24: 0.5574 | P24: 0.4472 | Q24: 0.7397 | R24: test_3 | W24: 45991.411 | X24: 50/50 split | Y24: HDBSCAN | Z24: Standard scaler | AA24: 0.8078 | AB24: 0.8205 | AC24: 0.8078 | AD24: 0.8782 | AE24: 0.7815 | AF24: 0.8563 | AG24: 0.7704 | AH24: 0.8573 | AI24: 0.7621 | AJ24: 0.9796 | AK24: 0.7056 | AL24: 0.9505 | AM24: 0.5611 | AN24: test_5
A25: 45991.306 | B25: 50/50 split | C25: AutoEncoder | D25: TF-IDF | E25: 0.8279 | F25: 0.8119 | G25: 0.8279 | H25: 0.8181 | I25: 0.7254 | J25: 0.6986 | K25: 0.7914 | L25: 0.8932 | M25: 0.9496 | N25: 0.8431 | O25: 0.5577 | P25: 0.4475 | Q25: 0.7398 | R25: test_4
A26: 45991.307 | B26: 50/50 split | C26: AutoEncoder | D26: TF-IDF | E26: 0.8284 | F26: 0.8123 | G26: 0.8284 | H26: 0.8186 | I26: 0.7261 | J26: 0.6991 | K26: 0.7924 | L26: 0.8935 | M26: 0.95 | N26: 0.8433 | O26: 0.5587 | P26: 0.4482 | Q26: 0.7414 | R26: test_5
A27: 45991.302 | B27: 50/50 split | C27: Logistic regression | D27: TF-IDF | E27: 0.8553 | F27: 0.8637 | G27: 0.8553 | H27: 0.901 | I27: 0.8299 | J27: 0.8932 | K27: 0.8096 | L27: 0.8956 | M27: 0.8196 | N27: 0.9872 | O27: 0.7643 | P27: 0.9668 | Q27: 0.6319 | R27: test_1
A28: 45991.302 | B28: 50/50 split | C28: Logistic regression | D28: TF-IDF | E28: 0.8586 | F28: 0.8667 | G28: 0.8586 | H28: 0.9022 | I28: 0.8331 | J28: 0.895 | K28: 0.8122 | L28: 0.8983 | M28: 0.8243 | N28: 0.9869 | O28: 0.768 | P28: 0.9657 | Q28: 0.6375 | R28: test_2
A29: 45991.302 | B29: 50/50 split | C29: Logistic regression | D29: TF-IDF | E29: 0.8817 | F29: 0.8876 | G29: 0.8817 | H29: 0.9116 | I29: 0.8568 | J29: 0.9082 | K29: 0.8335 | L29: 0.9165 | M29: 0.8568 | N29: 0.9851 | O29: 0.7972 | P29: 0.9595 | Q29: 0.6819 | R29: test_3
A30: 45991.302 | B30: 50/50 split | C30: Logistic regression | D30: TF-IDF | E30: 0.868 | F30: 0.8752 | G30: 0.868 | H30: 0.9055 | I30: 0.8426 | J30: 0.8998 | K30: 0.8203 | L30: 0.9058 | M30: 0.838 | N30: 0.9856 | O30: 0.7793 | P30: 0.9616 | Q30: 0.6551 | R30: test_4
A31: 45991.302 | B31: 50/50 split | C31: Logistic regression | D31: TF-IDF | E31: 0.8735 | F31: 0.8801 | G31: 0.8735 | H31: 0.907 | I31: 0.848 | J31: 0.9019 | K31: 0.8252 | L31: 0.9103 | M31: 0.8468 | N31: 0.984 | O31: 0.7857 | P31: 0.957 | Q31: 0.6665 | R31: test_5
A32: 45991.306 | B32: 50/50 split | C32: SVM | D32: TF-IDF | E32: 0.9048 | F32: 0.9068 | G32: 0.9048 | H32: 0.911 | I32: 0.876 | J32: 0.8934 | K32: 0.8624 | L32: 0.9358 | M32: 0.9156 | N32: 0.9568 | O32: 0.8163 | P32: 0.8711 | Q32: 0.7679 | R32: test_1
A33: 45991.306 | B33: 50/50 split | C33: SVM | D33: TF-IDF | E33: 0.9023 | F33: 0.9044 | G33: 0.9023 | H33: 0.9092 | I33: 0.873 | J33: 0.8917 | K33: 0.8586 | L33: 0.934 | M33: 0.9122 | N33: 0.9568 | O33: 0.8121 | P33: 0.8711 | Q33: 0.7605 | R33: test_2
A34: 45991.306 | B34: 50/50 split | C34: SVM | D34: TF-IDF | E34: 0.8123 | F34: 0.8249 | G34: 0.8123 | H34: 0.8842 | I34: 0.7871 | J34: 0.8646 | K34: 0.776 | L34: 0.8604 | M34: 0.7631 | N34: 0.986 | O34: 0.7139 | P34: 0.966 | Q34: 0.5661 | R34: test_3
A35: 45991.306 | B35: 50/50 split | C35: SVM | D35: TF-IDF | E35: 0.8992 | F35: 0.9017 | G35: 0.8992 | H35: 0.9076 | I35: 0.8699 | J35: 0.8913 | K35: 0.854 | L35: 0.9316 | M35: 0.9066 | N35: 0.9581 | O35: 0.8081 | P35: 0.8759 | Q35: 0.75 | R35: test_4
A36: 45991.306 | B36: 50/50 split | C36: SVM | D36: TF-IDF | E36: 0.8082 | F36: 0.8211 | G36: 0.8082 | H36: 0.883 | I36: 0.7832 | J36: 0.8622 | K36: 0.7733 | L36: 0.8568 | M36: 0.7574 | N36: 0.9862 | O36: 0.7096 | P36: 0.9669 | Q36: 0.5605 | R36: test_5
... A212: 45991.794 | B212: 70/30 split | C212: AutoEncoder | D212: TF-IDF | E212: 0.8299 | F212: 0.8142 | G212: 0.8299 | H212: 0.8204 | I212: 0.7291 | J212: 0.702 | K212: 0.7946 | L212: 0.8943 | M212: 0.9502 | N212: 0.8447 | O212: 0.5639 | P212: 0.4539 | Q212: 0.7445 | R212: test_1
A213: 45991.795 | B213: 70/30 split | C213: AutoEncoder | D213: TF-IDF | E213: 0.2424 | F213: 0.0946 | G213: 0.2424 | H213: 0.0587 | I213: 0.1951 | J213: 0.5 | K213: 0.1212 | O213: 0.3902 | P213: 1 | Q213: 0.2424 | R213: test_2
A214: 45991.795 | B214: 70/30 split | C214: AutoEncoder | D214: TF-IDF | E214: 0.2424 | F214: 0.0946 | G214: 0.2424 | H214: 0.0587 | I214: 0.1951 | J214: 0.5 | K214: 0.1212 | O214: 0.3902 | P214: 1 | Q214: 0.2424 | R214: test_3
A215: 45991.796 | B215: 70/30 split | C215: AutoEncoder | D215: TF-IDF | E215: 0.2424 | F215: 0.0946 | G215: 0.2424 | H215: 0.0587 | I215: 0.1951 | J215: 0.5 | K215: 0.1212 | O215: 0.3902 | P215: 1 | Q215: 0.2424 | R215: test_4
...

Sheet Summary supervised
B1: Benign Precision_avg | C1: Benign Recall_avg | D1: Benign F1-score_avg | E1: Attack Precision_avg | F1: Attack Recall_avg | G1: Attack F1-score_avg | H1: Accuracy
A2: Knn | B2: =AVERAGE('All results'!N132:N136,'All results'!N57:N61,'All results'!N212:N216) -> 0.95982727 | C2: =AVERAGE('All results'!M57:M61,'All results'!M132:M136,'All results'!M212:M216) -> 0.7914 | D2: =AVERAGE('All results'!L57:L61,'All results'!L132:L136,'All results'!L212:L216) -> 0.8579 | E2: =AVERAGE('All results'!Q57:Q61,'All results'!Q132:Q136,'All results'!Q212:Q216) -> 0.52976667 | F2: =AVERAGE('All results'!P57:P61,'All results'!P132:P136,'All results'!P212:P216) -> 0.91565333 | G2: =AVERAGE('All results'!O57:O61,'All results'!O132:O136,'All results'!O212:O216) -> 0.62734667 | H2: =AVERAGE('All results'!E57:E61,'All results'!E132:E136,'All results'!E212:E216) -> 0.66163333
A3: Logistic regression | B3: =AVERAGE('All results'!N62:N66,'All results'!N137:N141,'All results'!N217:N221) -> 0.83876364 | C3: =AVERAGE('All results'!M62:M66,'All results'!M137:M141,'All results'!M217:M221) -> 0.99280909 | D3: =AVERAGE('All results'!L62:L66,'All results'!L137:L141,'All results'!L217:L221) -> 0.9067 | E3: =AVERAGE('All results'!Q62:Q66,'All results'!Q137:Q141,'All results'!Q217:Q221) -> 0.65294 | F3: =AVERAGE('All results'!P62:P66,'All results'!P137:P141,'All results'!P217:P221) -> 0.53214667 | G3: =AVERAGE('All results'!O62:O66,'All results'!O137:O141,'All results'!O217:O221) -> 0.41090667 | H3: =AVERAGE('All results'!E62:E66,'All results'!E137:E141,'All results'!E217:E221) -> 0.68059333
A4: Random forest | B4: =AVERAGE('All results'!N67:N71,'All results'!N142:N146,'All results'!N222:N226) -> 0.9421 | C4: =AVERAGE('All results'!M67:M71,'All results'!M142:M146,'All results'!M222:M226) -> 0.98701333 | D4: =AVERAGE('All results'!L67:L71,'All results'!L142:L146,'All results'!L222:L226) -> 0.9628 | E4: =AVERAGE('All results'!Q67:Q71,'All results'!Q142:Q146,'All results'!Q222:Q226) -> 0.94697333 | F4: =AVERAGE('All results'!P67:P71,'All results'!P142:P146,'All results'!P222:P226) -> 0.79239333 | G4: =AVERAGE('All results'!O67:O71,'All results'!O142:O146,'All results'!O222:O226) -> 0.83806667 | H4: =AVERAGE('All results'!E67:E71,'All results'!E142:E146,'All results'!E222:E226) -> 0.93984
A5: SVM | B5: =AVERAGE('All results'!N72:N76,'All results'!N147:N151,'All results'!N227:N231) -> 0.84398 | C5: =AVERAGE('All results'!M72:M76,'All results'!M147:M151,'All results'!M227:M231) -> 0.95812 | D5: =AVERAGE('All results'!L72:L76,'All results'!L147:L151,'All results'!L227:L231) -> 0.89740667 | E5: =AVERAGE('All results'!Q72:Q76,'All results'!Q147:Q151,'All results'!Q227:Q231) -> 0.77694 | F5: =AVERAGE('All results'!P72:P76,'All results'!P147:P151,'All results'!P227:P231) -> 0.44645333 | G5: =AVERAGE('All results'!O72:O76,'All results'!O147:O151,'All results'!O227:O231) -> 0.56627333 | H5: =AVERAGE('All results'!E72:E76,'All results'!E147:E151,'All results'!E227:E231) -> 0.83409333
A6: ANN | B6: =AVERAGE('All results'!N2:N6,'All results'!N77:N81,'All results'!N152:N156) -> 0.89187333 | C6: =AVERAGE('All results'!M2:M6,'All results'!M77:M81,'All results'!M152:M156) -> 0.93676 | D6: =AVERAGE('All results'!L2:L6,'All results'!L77:L81,'All results'!L152:L156) -> 0.90888 | E6: =AVERAGE('All results'!Q2:Q6,'All results'!Q77:Q81,'All results'!Q152:Q156) -> 0.82053333 | F6: =AVERAGE('All results'!P2:P6,'All results'!P77:P81,'All results'!P152:P156) -> 0.61083333 | G6: =AVERAGE('All results'!O2:O6,'All results'!O77:O81,'All results'!O152:O156) -> 0.65207333 | H6: =AVERAGE('All results'!E2:E6,'All results'!E77:E81,'All results'!E152:E156) -> 0.85778

Sheet Sheet3
A1: 45990.343 | B1: 70/30 split | C1: Logistic regression | D1: TF-IDF | E1: 0.8977 | F1: 0.8975 | G1: 0.8975 | H1: 0.9008 | I1: test_5
A2: 45990.384 | B2: 70/30 split | C2: ANN | D2: TF-IDF | E2: 0.9156 | F2: 0.9163 | G2: 0.887 | H2: 0.9172
A3: 45990.651 | B3: 50/50 split | C3: ANN | D3: TF-IDF | E3: 0.9723 | F3: 0.9723 | G3: 0.9723 | H3: 0.9726 | I3: test_3
A4: 45989.203 | B4: 70/30 split | C4: Knn | D4: TF-IDF | E4: 0.9839 | F4: 0.984 | G4: 0.9784 | H4: 0.9845
A5: 45990.26 | B5: 50/50 split | C5: GMM | D5: TF-IDF | E5: 0.8236 | F5: 0.832 | G5: 0.7844 | H5: 0.8542
A6: 45990.249 | B6: 50/50 split | C6: HDBSCAN | D6: TF-IDF | E6: 0.7559 | F6: 0.7731 | G6: 0.7282 | H6: 0.8475
A7: 45988.613 | B7: 50/50 split | C7: Knn | D7: TF-IDF | E7: 0.9216 | F7: 0.917 | G7: 0.8813 | H7: 0.9252
A8: 45988.662 | B8: 50/50 split | C8: Knn | D8: TF-IDF | E8: 0.8217 | F8: 0.8167 | G8: 0.8167 | H8: 0.8613 | I8: test_2
A9: 45988.68 | B9: 50/50 split | C9: Knn | D9: TF-IDF | E9: 0.8184 | F9: 0.813 | G9: 0.813 | H9: 0.8603 | I9: test_3
A10: 45988.699 | B10: 50/50 split | C10: Knn | D10: TF-IDF | E10: 0.8226 | F10: 0.8174 | G10: 0.8174 | H10: 0.8637 | I10: test_4
A11: 45989.241 | B11: 70/30 split | C11: Knn | D11: TF-IDF | E11: 0.8293 | F11: 0.8266 | G11: 0.8266 | H11: 0.851 | I11: test_2
A12: 45989.542 | B12: 70/30 split | C12: Knn | D12: TF-IDF | E12: 0.8659 | F12: 0.8657 | G12: 0.8657 | H12: 0.8679 | I12: test_3
A13: 45989.568 | B13: 70/30 split | C13: Knn | D13: TF-IDF | E13: 0.8646 | F13: 0.8643 | G13: 0.8643 | H13: 0.8671 | I13: test_4
A14: 45989.594 | B14: 70/30 split | C14: Knn | D14: TF-IDF | E14: 0.8559 | F14: 0.8552 | G14: 0.8552 | H14: 0.8627 | I14: test_5
A15: 45990.413 | B15: 80/20 split | C15: ANN | D15: TF-IDF | E15: 0.9706 | F15: 0.9706 | G15: 0.9706 | H15: 0.9708 | I15: test_5
A16: 45989.629 | B16: 80/20 split | C16: Knn | D16: TF-IDF | E16: 0.992 | F16: 0.992 | G16: 0.9891 | H16: 0.9921
A17: 45989.664 | B17: 80/20 split | C17: Knn | D17: TF-IDF | E17: 0.8306 | F17: 0.828 | G17: 0.828 | H17: 0.8521 | I17: test_2
A18: 45989.694 | B18: 80/20 split | C18: Knn | D18: TF-IDF | E18: 0.834 | F18: 0.8316 | G18: 0.8316 | H18: 0.8546 | I18: test_3
A19: 45989.723 | B19: 80/20 split | C19: Knn | D19: TF-IDF | E19: 0.8324 | F19: 0.8298 | G19: 0.8298 | H19: 0.8543 | I19: test_4
A20: 45989.753 | B20: 80/20 split | C20: Knn | D20: TF-IDF | E20: 0.852 | F20: 0.8497 | G20: 0.8497 | H20: 0.8755 | I20: test_5
A21: 45990.315 | B21: 50/50 split | C21: Logistic regression | D21: TF-IDF | E21: 0.7692 | F21: 0.6798 | G21: 0.4804 | H21: 0.823
A22: 45990.315 | B22: 50/50 split | C22: Logistic regression | D22: TF-IDF | E22: 0.5409 | F22: 0.4182 | G22: 0.4182 | H22: 0.7604 | I22: test_2
A23: 45990.315 | B23: 50/50 split | C23: Logistic regression | D23: TF-IDF | E23: 0.8978 | F23: 0.8977 | G23: 0.8977 | H23: 0.8997 | I23: test_3
A24: 45990.315 | B24: 50/50 split | C24: Logistic regression | D24: TF-IDF | E24: 0.5454 | F24: 0.427 | G24: 0.427 | H24: 0.7617 | I24: test_4
A25: 45990.315 | B25: 50/50 split | C25: Logistic regression | D25: TF-IDF | E25: 0.8766 | F25: 0.8765 | G25: 0.8765 | H25: 0.8768 | I25: test_5
A26: 45990.343 | B26: 70/30 split | C26: Logistic regression | D26: TF-IDF | E26: 0.7604 | F26: 0.66 | G26: 0.4444 | H26: 0.8169
A27: 45990.343 | B27: 70/30 split | C27: Logistic regression | D27: TF-IDF | E27: 0.5221 | F27: 0.3807 | G27: 0.3807 | H27: 0.7555 | I27: test_2
A28: 45990.343 | B28: 70/30 split | C28: Logistic regression | D28: TF-IDF | E28: 0.8996 | F28: 0.8994 | G28: 0.8994 | H28: 0.9018 | I28: test_3
A29: 45990.343 | B29: 70/30 split | C29: Logistic regression | D29: TF-IDF | E29: 0.5266 | F29: 0.3899 | G29: 0.3899 | H29: 0.7568 | I29: test_4
A30: 45990.257 | B30: 50/50 split | C30: Auto-encoder | D30: TF-IDF | E30: 0.8071 | F30: 0.7959 | G30: 0.7078 | H30: 0.7936
A31: 45990.349 | B31: 80/20 split | C31: Logistic regression | D31: TF-IDF | E31: 0.7605 | F31: 0.6603 | G31: 0.4447 | H31: 0.8148
A32: 45990.349 | B32: 80/20 split | C32: Logistic regression | D32: TF-IDF | E32: 0.5206 | F32: 0.3775 | G32: 0.3775 | H32: 0.7552 | I32: test_2
A33: 45990.349 | B33: 80/20 split | C33: Logistic regression | D33: TF-IDF | E33: 0.8968 | F33: 0.8966 | G33: 0.8966 | H33: 0.8992 | I33: test_3
A34: 45990.349 | B34: 80/20 split | C34: Logistic regression | D34: TF-IDF | E34: 0.5219 | F34: 0.3802 | G34: 0.3802 | H34: 0.7555 | I34: test_4
A35: 45988.633 | B35: 50/50 split | C35: Random forest | D35: TF-IDF | E35: 0.8341 | F35: 0.802 | G35: 0.6968 | H35: 0.8536 | I35: n_estimators=300, max_depth=20, min_samples_split=2, min_samples_leaf=5, max_features='sqrt', random_state=42, n_jobs=-1
A36: 45989.195 | B36: 70/30 split | C36: Random forest | D36: TF-IDF | E36: 0.9961 | F36: 0.996 | G36: 0.9946 | H36: 0.996 | I36: n_estimators=300, max_depth=20, min_samples_split=2, min_samples_leaf=5, max_features='sqrt', random_state=42, n_jobs=-1
A37: 45990.411 | B37: 80/20 split | C37: ANN | D37: TF-IDF | E37: 0.9012 | F37: 0.8964 | G37: 0.8536 | H37: 0.9003
A38: 45990.347 | B38: 70/30 split | C38: SVM | D38: TF-IDF | E38: 0.8643 | F38: 0.8716 | G38: 0.8389 | H38: 0.9027
A39: 45990.347 | B39: 70/30 split | C39: SVM | D39: TF-IDF | E39: 0.8992 | F39: 0.8988 | G39: 0.8988 | H39: 0.9048 | I39: test_2
A40: 45990.347 | B40: 70/30 split | C40: SVM | D40: TF-IDF | E40: 0.9049 | F40: 0.9047 | G40: 0.9047 | H40: 0.9088 | I40: test_3
...
